Workbook
Name web_growth: Inputs!$E$6
Name mkt_growth: Inputs!$E$7
Name aov: Inputs!$E$8
Name returns_pp: Inputs!$E$9
Name gm_pp: Inputs!$E$10
Name carrier: Inputs!$E$11
Name productivity: Inputs!$E$12
Name pay_rise: Inputs!$E$13
Name nlw_2027: Inputs!$E$14
Name overheads: Inputs!$E$15
Name delivery_rate: Inputs!$B$18
Name mkt_ratio: Inputs!$B$19
Name fee_rate: Inputs!$B$20
Name orders_per_hour: Inputs!$B$21
Name oncost: Inputs!$B$22
Name nlw_2025: Inputs!$B$23
Name nlw_2026: Inputs!$B$24
Name salaried_month: Inputs!$B$25
Name inv_days: Inputs!$B$26
Name pay_days: Inputs!$B$27
Name capex_m: Inputs!$B$28
Name dep_m: Inputs!$B$29
Name tax_rate: Inputs!$B$30
Name fy26_profit: Inputs!$B$31
Name large_threshold: Inputs!$B$32
Name cash_open: Inputs!$B$33
Name quote: Inputs!$B$36
Name switch_cost: Inputs!$B$37
Name charge_exvat: Inputs!$B$38
Name affected: Inputs!$B$39
Name loss: Inputs!$B$40
Name price_rise: Inputs!$B$41
Name volume_loss: Inputs!$B$42

Sheet Cover
A1: DirectSportsGoods: rolling 18-month forecast
A2: DirectSportsGoods is a fictional company. All figures are made up.
A4: February 2026 to July 2027, built from FY26 actuals. Pick a scenario on the Inputs sheet (cell C3).
A6: Inputs: scenario drivers, fixed inputs and option assumptions
A7: Forecast: monthly P&L and cash, all live formulas
A8: Options: cash impact of the three options in the CFO memo, for the selected scenario
A9: Summary: all three scenarios side by side (values, rebuilt by src/forecast.py)
A10: Actuals: FY26 monthly actuals the forecast starts from
A12: Figures are in £k unless stated. Costs show in brackets. Blue cells are inputs.

Sheet Summary
A1: Scenario summary (£k)
A2: DirectSportsGoods is a fictional company. All figures are made up.
A3: FY27 runs Feb-26 to Jan-27. Values from src/forecast.py, which runs the same model as the Forecast sheet.
B5: Base | C5: Downside | D5: Upside
A6: FY27 net revenue | B6: 54309191 | C6: 48303775 | D6: 59026407
A7: FY27 EBITDA | B7: 4714612 | C7: 2058609.1 | D7: 6472795.5
A8: FY27 operating profit | B8: 3994612 | C8: 1338609.1 | D8: 5752795.5
A9: Cash at 31 Jan 2027 | B9: 8913602.6 | C9: 7123140.5 | D9: 10152065
A10: Lowest month-end cash, 18 months | B10: 6163240.8 | C10: 5695083.7 | D10: 6247029.1
A11: Cash at 31 Jul 2027 | B11: 10032062 | C11: 7025983.9 | D11: 12295954
A12: Option A, 18-month cash impact | B12: 319815.89 | C12: 639640.47 | D12: 362180.81
A13: Option B, 18-month cash impact | B13: 18341.86 | C13: 58689.11 | D13: -7883.33
A14: Option C, 18-month cash impact | B14: 745934.64 | C14: 673493.75 | D14: 816259.03

Sheet Inputs
A1: Inputs
A2: DirectSportsGoods is a fictional company. All figures are made up.
A3: Scenario | C3: Base
A5: Scenario driver | B5: Base | C5: Downside | D5: Upside | E5: Live
A6: Website orders vs same month last year | B6: 0.05 | C6: -0.03 | D6: 0.1 | E6: =INDEX(B6:D6,MATCH($C$3,$B$5:$D$5,0))
A7: Marketplace orders vs same month last year | B7: 0.15 | C7: 0.05 | D7: 0.25 | E7: =INDEX(B7:D7,MATCH($C$3,$B$5:$D$5,0))
A8: Average order value vs last year | B8: 0.02 | C8: 0 | D8: 0.03 | E8: =INDEX(B8:D8,MATCH($C$3,$B$5:$D$5,0))
A9: Returns rate change (points) | B9: 0 | C9: 0.01 | D9: -0.01 | E9: =INDEX(B9:D9,MATCH($C$3,$B$5:$D$5,0))
A10: Gross margin change (points) | B10: 0 | C10: -0.01 | D10: 0.005 | E10: =INDEX(B10:D10,MATCH($C$3,$B$5:$D$5,0))
A11: Carrier rate change from today | B11: 0 | C11: 0.05 | D11: 0 | E11: =INDEX(B11:D11,MATCH($C$3,$B$5:$D$5,0))
A12: Warehouse orders per hour change | B12: 0 | C12: -0.05 | D12: 0.05 | E12: =INDEX(B12:D12,MATCH($C$3,$B$5:$D$5,0))
A13: Salaried pay rise each April | B13: 0.03 | C13: 0.04 | D13: 0.03 | E13: =INDEX(B13:D13,MATCH($C$3,$B$5:$D$5,0))
A14: National Living Wage rise, April 2027 | B14: 0.03 | C14: 0.04 | D14: 0.03 | E14: =INDEX(B14:D14,MATCH($C$3,$B$5:$D$5,0))
A15: Overhead inflation | B15: 0.03 | C15: 0.04 | D15: 0.02 | E15: =INDEX(B15:D15,MATCH($C$3,$B$5:$D$5,0))
A17: Fixed input | B17: Value | C17: Source
A18: Delivery cost per order today (Sep-25 to Jan-26 average) | B18: 4.7166 | C18: Derived from FY26 actuals
A19: Marketing % of website net revenue | B19: 0.0712 | C19: FY26 actual
A20: Marketplace fees % of net revenue | B20: 0.15 | C20: Amazon UK seller fees, Sports and Outdoors
A21: Warehouse orders per labour hour | B21: 5.504 | C21: Derived: FY26 orders / warehouse hours (45% of payroll at NLW)
A22: Employer NI and pension on pay | B22: 0.12 | C22: Company assumption, as in the P2 payroll data
A23: National Living Wage from April 2025 | B23: 12.21 | C23: gov.uk national minimum wage rates
A24: National Living Wage from April 2026 | B24: 12.71 | C24: gov.uk national minimum wage rates
A25: Salaried payroll per month, FY26 average | B25: 311238.48 | C25: FY26 actual (55% of payroll)
A26: Inventory days | B26: 172 | C26: Frasers AR 2026
A27: Trade and other payables days | B27: 118 | C27: Frasers AR 2026
A28: Capital expenditure per month | B28: 70000 | C28: Company assumption
A29: Depreciation per month | B29: 60000 | C29: Company assumption
... A33: Cash at 31 January 2026 | B33: 6346305.2 | C33: P1 pack, Cash page
A35: Option assumption | B35: Value | C35: Source
A36: Option A: second carrier's quoted rate per order | B36: 4.45 | C36: Fictional quote or company assumption
A37: Option A: one-off cost to switch carrier | B37: 150000 | C37: Fictional quote or company assumption
A38: Option B: delivery charge per order, ex VAT (£1.99 inc VAT) | B38: 1.6583 | C38: Fictional quote or company assumption
A39: Option B: share of website orders below the free-delivery threshold | B39: 0.35 | C39: Fictional quote or company assumption
A40: Option B: share of those orders lost to the charge | B40: 0.08 | C40: Fictional quote or company assumption
A41: Option C: price rise, both channels | B41: 0.02 | C41: Fictional quote or company assumption
A42: Option C: orders lost to the price rise | B42: 0.025 | C42: Fictional quote or company assumption

Sheet Actuals
A1: FY26 actuals (£)
A2: DirectSportsGoods is a fictional company. All figures are made up.
A3: From the P1 pack. The P2 close reproduces these figures from the ledger.
B5: Feb-25 | C5: Mar-25 | D5: Apr-25 | E5: May-25 | F5: Jun-25 | G5: Jul-25 | H5: Aug-25 | I5: Sep-25 | J5: Oct-25 | K5: Nov-25 | L5: Dec-25 | M5: Jan-26
A6: Website orders | B6: 43576.42 | C6: 48025.5 | D6: 49564.72 | E6: 57184.42 | F6: 68776.58 | G6: 66980.52 | H6: 71982.81 | I6: 62419.42 | J6: 56313.68 | K6: 70380.44 | L6: 74863.6 | M6: 65732.5
A7: Website gross sales | B7: 2723464 | C7: 2955062.5 | D7: 3032172.8 | E7: 3565687.5 | F7: 4251791.3 | G7: 4197492.6 | H7: 4458264.3 | I7: 3846684.7 | J7: 3495833 | K7: 4362471.3 | L7: 4627449.1 | M7: 4037830.7
A8: Website returns | B8: 741088.37 | C8: 837202.52 | D8: 856395.24 | E8: 994871.73 | F8: 1227833.6 | G8: 1177621.8 | H8: 1252071.9 | I8: 1101769.7 | J8: 984834.62 | K8: 1232044 | L8: 1286195 | M8: 1116770.8
A9: Website cost of goods sold | B9: 970548.68 | C9: 1046072.8 | D9: 1051967.4 | E9: 1271370.6 | F9: 1524153.8 | G9: 1463823.6 | H9: 1579652.8 | I9: 1333547 | J9: 1217410.6 | K9: 1524282 | L9: 1644341.5 | M9: 1541713.5
A10: Marketplace orders | B10: 24154.9 | C10: 27451.68 | D10: 28597.8 | E10: 35553.38 | F10: 46968.2 | G10: 48027.49 | H10: 49907.29 | I10: 43600.85 | J10: 43988.28 | K10: 53121.82 | L10: 58604.42 | M10: 47018.55
A11: Marketplace gross sales | B11: 1083032.5 | C11: 1238719.1 | D11: 1272506.6 | E11: 1618311.6 | F11: 2091624.4 | G11: 2135860 | H11: 2246897.6 | I11: 1973374.1 | J11: 1997008.3 | K11: 2360882.2 | L11: 2627702.8 | M11: 2104630.7
A12: Marketplace returns | B12: 303171.92 | C12: 344597.39 | D12: 351371.55 | E12: 441265.18 | F12: 580353.22 | G12: 575830.62 | H12: 632262.14 | I12: 556694.83 | J12: 563345.33 | K12: 671535.79 | L12: 739707.63 | M12: 589087.79
A13: Marketplace cost of goods sold | B13: 383693.81 | C13: 436006.19 | D13: 449272 | E13: 576198.68 | F13: 726695.69 | G13: 758138.73 | H13: 782010.26 | I13: 692745.85 | J13: 693072.76 | K13: 821248.35 | L13: 927224.89 | M13: 801797.74
A14: Payroll | B14: 531032.89 | C14: 522471.9 | D14: 537186.84 | E14: 567536.56 | F14: 570302.91 | G14: 564102.69 | H14: 581545.21 | I14: 567987.11 | J14: 573208.81 | K14: 602309.34 | L14: 605034.97 | M14: 567938.51
A15: Other overheads | B15: 287562.74 | C15: 316370.64 | D15: 314153.42 | E15: 302313.78 | F15: 295207.86 | G15: 309015.12 | H15: 297193.01 | I15: 305420.93 | J15: 314823.14 | K15: 295057.96 | L15: 302347.42 | M15: 293471.88
A16: Cost of goods sold, total | B16: =B9+B13 | C16: =C9+C13 | D16: =D9+D13 | E16: =E9+E13 | F16: =F9+F13 | G16: =G9+G13 | H16: =H9+H13 | I16: =I9+I13 | ... M16: =M9+M13

Sheet Forecast
A1: Rolling forecast, Feb-26 to Jul-27 (£k)
A2: DirectSportsGoods is a fictional company. All figures are made up.
A3: ="Scenario: "&Inputs!$C$3
B5: 46054 | C5: 46082 | D5: 46113 | E5: 46143 | F5: 46174 | G5: 46204 | H5: 46235 | I5: 46266 | J5: 46296 | K5: 46327 | L5: 46357 | M5: 46388 | N5: 46419 | O5: 46447 | P5: 46478 | Q5: 46508 | R5: 46539 | S5: 46569 | T5: FY27 | U5: 18 months
A6: Website
A7: Orders (000s) | B7: =Actuals!B6*(1+web_growth) | C7: =Actuals!C6*(1+web_growth) | D7: =Actuals!D6*(1+web_growth) | E7: =Actuals!E6*(1+web_growth) | F7: =Actuals!F6*(1+web_growth) | G7: =Actuals!G6*(1+web_growth) | H7: =Actuals!H6*(1+web_growth) | I7: =Actuals!I6*(1+web_growth) | ... M7: =Actuals!M6*(1+web_growth) | N7: =B7*(1+web_growth) | O7: =C7*(1+web_growth) | P7: =D7*(1+web_growth) | Q7: =E7*(1+web_growth) | R7: =F7*(1+web_growth) | S7: =G7*(1+web_growth) | T7: =SUM(B7:M7) | U7: =SUM(B7:S7)
A8: Average order value (£) | B8: =Actuals!B7/Actuals!B6*(1+aov) | C8: =Actuals!C7/Actuals!C6*(1+aov) | D8: =Actuals!D7/Actuals!D6*(1+aov) | E8: =Actuals!E7/Actuals!E6*(1+aov) | F8: =Actuals!F7/Actuals!F6*(1+aov) | G8: =Actuals!G7/Actuals!G6*(1+aov) | H8: =Actuals!H7/Actuals!H6*(1+aov) | I8: =Actuals!I7/Actuals!I6*(1+aov) | ... M8: =Actuals!M7/Actuals!M6*(1+aov) | N8: =B8*(1+aov) | O8: =C8*(1+aov) | P8: =D8*(1+aov) | Q8: =E8*(1+aov) | R8: =F8*(1+aov) | S8: =G8*(1+aov)
A9: Gross sales | B9: =B7*B8 | C9: =C7*C8 | D9: =D7*D8 | E9: =E7*E8 | F9: =F7*F8 | G9: =G7*G8 | H9: =H7*H8 | I9: =I7*I8 | ... S9: =S7*S8 | T9: =SUM(B9:M9) | U9: =SUM(B9:S9)
A10: Returns rate | B10: =Actuals!B8/Actuals!B7+returns_pp | C10: =Actuals!C8/Actuals!C7+returns_pp | D10: =Actuals!D8/Actuals!D7+returns_pp | E10: =Actuals!E8/Actuals!E7+returns_pp | F10: =Actuals!F8/Actuals!F7+returns_pp | G10: =Actuals!G8/Actuals!G7+returns_pp | H10: =Actuals!H8/Actuals!H7+returns_pp | I10: =Actuals!I8/Actuals!I7+returns_pp | ... M10: =Actuals!M8/Actuals!M7+returns_pp | N10: =Actuals!B8/Actuals!B7+returns_pp | O10: =Actuals!C8/Actuals!C7+returns_pp | P10: =Actuals!D8/Actuals!D7+returns_pp | Q10: =Actuals!E8/Actuals!E7+returns_pp | R10: =Actuals!F8/Actuals!F7+returns_pp | S10: =Actuals!G8/Actuals!G7+returns_pp
A11: Returns | B11: =-B9*B10 | C11: =-C9*C10 | D11: =-D9*D10 | E11: =-E9*E10 | F11: =-F9*F10 | G11: =-G9*G10 | H11: =-H9*H10 | I11: =-I9*I10 | ... S11: =-S9*S10 | T11: =SUM(B11:M11) | U11: =SUM(B11:S11)
A12: Net revenue | B12: =B9+B11 | C12: =C9+C11 | D12: =D9+D11 | E12: =E9+E11 | F12: =F9+F11 | G12: =G9+G11 | H12: =H9+H11 | I12: =I9+I11 | ... S12: =S9+S11 | T12: =SUM(B12:M12) | U12: =SUM(B12:S12)
A13: Gross margin % | B13: =1-Actuals!B9/(Actuals!B7-Actuals!B8)+gm_pp | C13: =1-Actuals!C9/(Actuals!C7-Actuals!C8)+gm_pp | D13: =1-Actuals!D9/(Actuals!D7-Actuals!D8)+gm_pp | E13: =1-Actuals!E9/(Actuals!E7-Actuals!E8)+gm_pp | F13: =1-Actuals!F9/(Actuals!F7-Actuals!F8)+gm_pp | G13: =1-Actuals!G9/(Actuals!G7-Actuals!G8)+gm_pp | H13: =1-Actuals!H9/(Actuals!H7-Actuals!H8)+gm_pp | I13: =1-Actuals!I9/(Actuals!I7-Actuals!I8)+gm_pp | ... M13: =1-Actuals!M9/(Actuals!M7-Actuals!M8)+gm_pp | N13: =1-Actuals!B9/(Actuals!B7-Actuals!B8)+gm_pp | O13: =1-Actuals!C9/(Actuals!C7-Actuals!C8)+gm_pp | P13: =1-Actuals!D9/(Actuals!D7-Actuals!D8)+gm_pp | Q13: =1-Actuals!E9/(Actuals!E7-Actuals!E8)+gm_pp | R13: =1-Actuals!F9/(Actuals!F7-Actuals!F8)+gm_pp | S13: =1-Actuals!G9/(Actuals!G7-Actuals!G8)+gm_pp
A14: Cost of goods sold | B14: =-B12*(1-B13) | C14: =-C12*(1-C13) | D14: =-D12*(1-D13) | E14: =-E12*(1-E13) | F14: =-F12*(1-F13) | G14: =-G12*(1-G13) | H14: =-H12*(1-H13) | I14: =-I12*(1-I13) | ... S14: =-S12*(1-S13) | T14: =SUM(B14:M14) | U14: =SUM(B14:S14)
A15: Delivery and fulfilment | B15: =-B7*delivery_rate*(1+carrier) | C15: =-C7*delivery_rate*(1+carrier) | D15: =-D7*delivery_rate*(1+carrier) | E15: =-E7*delivery_rate*(1+carrier) | F15: =-F7*delivery_rate*(1+carrier) | G15: =-G7*delivery_rate*(1+carrier) | H15: =-H7*delivery_rate*(1+carrier) | I15: =-I7*delivery_rate*(1+carrier) | ... S15: =-S7*delivery_rate*(1+carrier) | T15: =SUM(B15:M15) | U15: =SUM(B15:S15)
A16: Marketing | B16: =-B12*mkt_ratio | C16: =-C12*mkt_ratio | D16: =-D12*mkt_ratio | E16: =-E12*mkt_ratio | F16: =-F12*mkt_ratio | G16: =-G12*mkt_ratio | H16: =-H12*mkt_ratio | I16: =-I12*mkt_ratio | ... S16: =-S12*mkt_ratio | T16: =SUM(B16:M16) | U16: =SUM(B16:S16)
A17: Contribution | B17: =B12+B14+B15+B16 | C17: =C12+C14+C15+C16 | D17: =D12+D14+D15+D16 | E17: =E12+E14+E15+E16 | F17: =F12+F14+F15+F16 | G17: =G12+G14+G15+G16 | H17: =H12+H14+H15+H16 | I17: =I12+I14+I15+I16 | ... S17: =S12+S14+S15+S16 | T17: =SUM(B17:M17) | U17: =SUM(B17:S17)
A19: Marketplace
A20: Orders (000s) | B20: =Actuals!B10*(1+mkt_growth) | C20: =Actuals!C10*(1+mkt_growth) | D20: =Actuals!D10*(1+mkt_growth) | E20: =Actuals!E10*(1+mkt_growth) | F20: =Actuals!F10*(1+mkt_growth) | G20: =Actuals!G10*(1+mkt_growth) | H20: =Actuals!H10*(1+mkt_growth) | I20: =Actuals!I10*(1+mkt_growth) | ... M20: =Actuals!M10*(1+mkt_growth) | N20: =B20*(1+mkt_growth) | O20: =C20*(1+mkt_growth) | P20: =D20*(1+mkt_growth) | Q20: =E20*(1+mkt_growth) | R20: =F20*(1+mkt_growth) | S20: =G20*(1+mkt_growth) | T20: =SUM(B20:M20) | U20: =SUM(B20:S20)
A21: Average order value (£) | B21: =Actuals!B11/Actuals!B10*(1+aov) | C21: =Actuals!C11/Actuals!C10*(1+aov) | D21: =Actuals!D11/Actuals!D10*(1+aov) | E21: =Actuals!E11/Actuals!E10*(1+aov) | F21: =Actuals!F11/Actuals!F10*(1+aov) | G21: =Actuals!G11/Actuals!G10*(1+aov) | H21: =Actuals!H11/Actuals!H10*(1+aov) | I21: =Actuals!I11/Actuals!I10*(1+aov) | ... M21: =Actuals!M11/Actuals!M10*(1+aov) | N21: =B21*(1+aov) | O21: =C21*(1+aov) | P21: =D21*(1+aov) | Q21: =E21*(1+aov) | R21: =F21*(1+aov) | S21: =G21*(1+aov)
A22: Gross sales | B22: =B20*B21 | C22: =C20*C21 | D22: =D20*D21 | E22: =E20*E21 | F22: =F20*F21 | G22: =G20*G21 | H22: =H20*H21 | I22: =I20*I21 | ... S22: =S20*S21 | T22: =SUM(B22:M22) | U22: =SUM(B22:S22)
A23: Returns rate | B23: =Actuals!B12/Actuals!B11+returns_pp | C23: =Actuals!C12/Actuals!C11+returns_pp | D23: =Actuals!D12/Actuals!D11+returns_pp | E23: =Actuals!E12/Actuals!E11+returns_pp | F23: =Actuals!F12/Actuals!F11+returns_pp | G23: =Actuals!G12/Actuals!G11+returns_pp | H23: =Actuals!H12/Actuals!H11+returns_pp | I23: =Actuals!I12/Actuals!I11+returns_pp | ... M23: =Actuals!M12/Actuals!M11+returns_pp | N23: =Actuals!B12/Actuals!B11+returns_pp | O23: =Actuals!C12/Actuals!C11+returns_pp | P23: =Actuals!D12/Actuals!D11+returns_pp | Q23: =Actuals!E12/Actuals!E11+returns_pp | R23: =Actuals!F12/Actuals!F11+returns_pp | S23: =Actuals!G12/Actuals!G11+returns_pp
A24: Returns | B24: =-B22*B23 | C24: =-C22*C23 | D24: =-D22*D23 | E24: =-E22*E23 | F24: =-F22*F23 | G24: =-G22*G23 | H24: =-H22*H23 | I24: =-I22*I23 | ... S24: =-S22*S23 | T24: =SUM(B24:M24) | U24: =SUM(B24:S24)
A25: Net revenue | B25: =B22+B24 | C25: =C22+C24 | D25: =D22+D24 | E25: =E22+E24 | F25: =F22+F24 | G25: =G22+G24 | H25: =H22+H24 | I25: =I22+I24 | ... S25: =S22+S24 | T25: =SUM(B25:M25) | U25: =SUM(B25:S25)
A26: Gross margin % | B26: =1-Actuals!B13/(Actuals!B11-Actuals!B12)+gm_pp | C26: =1-Actuals!C13/(Actuals!C11-Actuals!C12)+gm_pp | D26: =1-Actuals!D13/(Actuals!D11-Actuals!D12)+gm_pp | E26: =1-Actuals!E13/(Actuals!E11-Actuals!E12)+gm_pp | F26: =1-Actuals!F13/(Actuals!F11-Actuals!F12)+gm_pp | G26: =1-Actuals!G13/(Actuals!G11-Actuals!G12)+gm_pp | H26: =1-Actuals!H13/(Actuals!H11-Actuals!H12)+gm_pp | I26: =1-Actuals!I13/(Actuals!I11-Actuals!I12)+gm_pp | ... M26: =1-Actuals!M13/(Actuals!M11-Actuals!M12)+gm_pp | N26: =1-Actuals!B13/(Actuals!B11-Actuals!B12)+gm_pp | O26: =1-Actuals!C13/(Actuals!C11-Actuals!C12)+gm_pp | P26: =1-Actuals!D13/(Actuals!D11-Actuals!D12)+gm_pp | Q26: =1-Actuals!E13/(Actuals!E11-Actuals!E12)+gm_pp | R26: =1-Actuals!F13/(Actuals!F11-Actuals!F12)+gm_pp | S26: =1-Actuals!G13/(Actuals!G11-Actuals!G12)+gm_pp
A27: Cost of goods sold | B27: =-B25*(1-B26) | C27: =-C25*(1-C26) | D27: =-D25*(1-D26) | E27: =-E25*(1-E26) | F27: =-F25*(1-F26) | G27: =-G25*(1-G26) | H27: =-H25*(1-H26) | I27: =-I25*(1-I26) | ... S27: =-S25*(1-S26) | T27: =SUM(B27:M27) | U27: =SUM(B27:S27)
A28: Delivery and fulfilment | B28: =-B20*delivery_rate*(1+carrier) | C28: =-C20*delivery_rate*(1+carrier) | D28: =-D20*delivery_rate*(1+carrier) | E28: =-E20*delivery_rate*(1+carrier) | F28: =-F20*delivery_rate*(1+carrier) | G28: =-G20*delivery_rate*(1+carrier) | H28: =-H20*delivery_rate*(1+carrier) | I28: =-I20*delivery_rate*(1+carrier) | ... S28: =-S20*delivery_rate*(1+carrier) | T28: =SUM(B28:M28) | U28: =SUM(B28:S28)
A29: Marketplace fees | B29: =-B25*fee_rate | C29: =-C25*fee_rate | D29: =-D25*fee_rate | E29: =-E25*fee_rate | F29: =-F25*fee_rate | G29: =-G25*fee_rate | H29: =-H25*fee_rate | I29: =-I25*fee_rate | ... S29: =-S25*fee_rate | T29: =SUM(B29:M29) | U29: =SUM(B29:S29)
A30: Contribution | B30: =B25+B27+B28+B29 | C30: =C25+C27+C28+C29 | D30: =D25+D27+D28+D29 | E30: =E25+E27+E28+E29 | F30: =F25+F27+F28+F29 | G30: =G25+G27+G28+G29 | H30: =H25+H27+H28+H29 | I30: =I25+I27+I28+I29 | ... S30: =S25+S27+S28+S29 | T30: =SUM(B30:M30) | U30: =SUM(B30:S30)
A32: Central
A33: Total orders (000s) | B33: =B7+B20 | C33: =C7+C20 | D33: =D7+D20 | E33: =E7+E20 | F33: =F7+F20 | G33: =G7+G20 | H33: =H7+H20 | I33: =I7+I20 | ... S33: =S7+S20 | T33: =SUM(B33:M33) | U33: =SUM(B33:S33)
A34: Warehouse hours (000s) | B34: =B33/(orders_per_hour*(1+productivity)) | C34: =C33/(orders_per_hour*(1+productivity)) | D34: =D33/(orders_per_hour*(1+productivity)) | E34: =E33/(orders_per_hour*(1+productivity)) | F34: =F33/(orders_per_hour*(1+productivity)) | G34: =G33/(orders_per_hour*(1+productivity)) | H34: =H33/(orders_per_hour*(1+productivity)) | I34: =I33/(orders_per_hour*(1+productivity)) | ... S34: =S33/(orders_per_hour*(1+productivity)) | T34: =SUM(B34:M34) | U34: =SUM(B34:S34)
A35: National Living Wage (£/hour) | B35: =IF(B$5<DATE(2026,4,1),nlw_2025,IF(B$5<DATE(2027,4,1),nlw_2026,nlw_2026*(1+nlw_2027))) | C35: =IF(C$5<DATE(2026,4,1),nlw_2025,IF(C$5<DATE(2027,4,1),nlw_2026,nlw_2026*(1+nlw_2027))) | D35: =IF(D$5<DATE(2026,4,1),nlw_2025,IF(D$5<DATE(2027,4,1),nlw_2026,nlw_2026*(1+nlw_2027))) | E35: =IF(E$5<DATE(2026,4,1),nlw_2025,IF(E$5<DATE(2027,4,1),nlw_2026,nlw_2026*(1+nlw_2027))) | F35: =IF(F$5<DATE(2026,4,1),nlw_2025,IF(F$5<DATE(2027,4,1),nlw_2026,nlw_2026*(1+nlw_2027))) | G35: =IF(G$5<DATE(2026,4,1),nlw_2025,IF(G$5<DATE(2027,4,1),nlw_2026,nlw_2026*(1+nlw_2027))) | H35: =IF(H$5<DATE(2026,4,1),nlw_2025,IF(H$5<DATE(2027,4,1),nlw_2026,nlw_2026*(1+nlw_2027))) | I35: =IF(I$5<DATE(2026,4,1),nlw_2025,IF(I$5<DATE(2027,4,1),nlw_2026,nlw_2026*(1+nlw_2027))) | ... S35: =IF(S$5<DATE(2026,4,1),nlw_2025,IF(S$5<DATE(2027,4,1),nlw_2026,nlw_2026*(1+nlw_2027)))
A36: Warehouse payroll | B36: =-B34*B35*(1+oncost) | C36: =-C34*C35*(1+oncost) | D36: =-D34*D35*(1+oncost) | E36: =-E34*E35*(1+oncost) | F36: =-F34*F35*(1+oncost) | G36: =-G34*G35*(1+oncost) | H36: =-H34*H35*(1+oncost) | I36: =-I34*I35*(1+oncost) | ... S36: =-S34*S35*(1+oncost) | T36: =SUM(B36:M36) | U36: =SUM(B36:S36)
A37: Salaried payroll | B37: =-salaried_month*(1+pay_rise)^((B$5>=DATE(2026,4,1))+(B$5>=DATE(2027,4,1))) | C37: =-salaried_month*(1+pay_rise)^((C$5>=DATE(2026,4,1))+(C$5>=DATE(2027,4,1))) | D37: =-salaried_month*(1+pay_rise)^((D$5>=DATE(2026,4,1))+(D$5>=DATE(2027,4,1))) | E37: =-salaried_month*(1+pay_rise)^((E$5>=DATE(2026,4,1))+(E$5>=DATE(2027,4,1))) | F37: =-salaried_month*(1+pay_rise)^((F$5>=DATE(2026,4,1))+(F$5>=DATE(2027,4,1))) | G37: =-salaried_month*(1+pay_rise)^((G$5>=DATE(2026,4,1))+(G$5>=DATE(2027,4,1))) | H37: =-salaried_month*(1+pay_rise)^((H$5>=DATE(2026,4,1))+(H$5>=DATE(2027,4,1))) | I37: =-salaried_month*(1+pay_rise)^((I$5>=DATE(2026,4,1))+(I$5>=DATE(2027,4,1))) | ... S37: =-salaried_month*(1+pay_rise)^((S$5>=DATE(2026,4,1))+(S$5>=DATE(2027,4,1))) | T37: =SUM(B37:M37) | U37: =SUM(B37:S37)
A38: Other overheads | B38: =-Actuals!B15*(1+overheads)^1 | C38: =-Actuals!C15*(1+overheads)^1 | D38: =-Actuals!D15*(1+overheads)^1 | E38: =-Actuals!E15*(1+overheads)^1 | F38: =-Actuals!F15*(1+overheads)^1 | G38: =-Actuals!G15*(1+overheads)^1 | H38: =-Actuals!H15*(1+overheads)^1 | I38: =-Actuals!I15*(1+overheads)^1 | ... M38: =-Actuals!M15*(1+overheads)^1 | N38: =-Actuals!B15*(1+overheads)^2 | O38: =-Actuals!C15*(1+overheads)^2 | P38: =-Actuals!D15*(1+overheads)^2 | Q38: =-Actuals!E15*(1+overheads)^2 | R38: =-Actuals!F15*(1+overheads)^2 | S38: =-Actuals!G15*(1+overheads)^2 | T38: =SUM(B38:M38) | U38: =SUM(B38:S38)
A39: EBITDA | B39: =B17+B30+B36+B37+B38 | C39: =C17+C30+C36+C37+C38 | D39: =D17+D30+D36+D37+D38 | E39: =E17+E30+E36+E37+E38 | F39: =F17+F30+F36+F37+F38 | G39: =G17+G30+G36+G37+G38 | H39: =H17+H30+H36+H37+H38 | I39: =I17+I30+I36+I37+I38 | ... S39: =S17+S30+S36+S37+S38 | T39: =SUM(B39:M39) | U39: =SUM(B39:S39)
A40: Depreciation | B40: =-dep_m | C40: =-dep_m | D40: =-dep_m | E40: =-dep_m | F40: =-dep_m | G40: =-dep_m | H40: =-dep_m | I40: =-dep_m | ... S40: =-dep_m | T40: =SUM(B40:M40) | U40: =SUM(B40:S40)
A41: Operating profit | B41: =B39+B40 | C41: =C39+C40 | D41: =D39+D40 | E41: =E39+E40 | F41: =F39+F40 | G41: =G39+G40 | H41: =H39+H40 | I41: =I39+I40 | ... S41: =S39+S40 | T41: =SUM(B41:M41) | U41: =SUM(B41:S41)
A43: Cash
A44: Cost of goods sold, total | B44: =-(B14+B27) | C44: =-(C14+C27) | D44: =-(D14+D27) | E44: =-(E14+E27) | F44: =-(F14+F27) | G44: =-(G14+G27) | H44: =-(H14+H27) | I44: =-(I14+I27) | ... S44: =-(S14+S27)
...

Sheet Options
A1: Options: cash impact against doing nothing (£k)
A2: DirectSportsGoods is a fictional company. All figures are made up.
A3: ="Scenario: "&Inputs!$C$3
B5: 46054 | C5: 46082 | D5: 46113 | E5: 46143 | F5: 46174 | G5: 46204 | H5: 46235 | I5: 46266 | J5: 46296 | K5: 46327 | L5: 46357 | M5: 46388 | N5: 46419 | O5: 46447 | P5: 46478 | Q5: 46508 | R5: 46539 | S5: 46569 | T5: FY27 | U5: 18 months
A6: Website contribution per order (£) | B6: =(Forecast!B12+Forecast!B14+Forecast!B15)/Forecast!B7 | C6: =(Forecast!C12+Forecast!C14+Forecast!C15)/Forecast!C7 | D6: =(Forecast!D12+Forecast!D14+Forecast!D15)/Forecast!D7 | E6: =(Forecast!E12+Forecast!E14+Forecast!E15)/Forecast!E7 | F6: =(Forecast!F12+Forecast!F14+Forecast!F15)/Forecast!F7 | G6: =(Forecast!G12+Forecast!G14+Forecast!G15)/Forecast!G7 | H6: =(Forecast!H12+Forecast!H14+Forecast!H15)/Forecast!H7 | I6: =(Forecast!I12+Forecast!I14+Forecast!I15)/Forecast!I7 | ... S6: =(Forecast!S12+Forecast!S14+Forecast!S15)/Forecast!S7
A7: Marketplace contribution per order (£) | B7: =(Forecast!B25+Forecast!B27+Forecast!B28+Forecast!B29)/Forecast!B20 | C7: =(Forecast!C25+Forecast!C27+Forecast!C28+Forecast!C29)/Forecast!C20 | D7: =(Forecast!D25+Forecast!D27+Forecast!D28+Forecast!D29)/Forecast!D20 | E7: =(Forecast!E25+Forecast!E27+Forecast!E28+Forecast!E29)/Forecast!E20 | F7: =(Forecast!F25+Forecast!F27+Forecast!F28+Forecast!F29)/Forecast!F20 | G7: =(Forecast!G25+Forecast!G27+Forecast!G28+Forecast!G29)/Forecast!G20 | H7: =(Forecast!H25+Forecast!H27+Forecast!H28+Forecast!H29)/Forecast!H20 | I7: =(Forecast!I25+Forecast!I27+Forecast!I28+Forecast!I29)/Forecast!I20 | ... S7: =(Forecast!S25+Forecast!S27+Forecast!S28+Forecast!S29)/Forecast!S20
A8: A. Switch carrier | B8: 0 | C8: =-switch_cost | D8: 0 | E8: =(delivery_rate*(1+carrier)-quote)*Forecast!E33 | F8: =(delivery_rate*(1+carrier)-quote)*Forecast!F33 | G8: =(delivery_rate*(1+carrier)-quote)*Forecast!G33 | H8: =(delivery_rate*(1+carrier)-quote)*Forecast!H33 | I8: =(delivery_rate*(1+carrier)-quote)*Forecast!I33 | J8: =(delivery_rate*(1+carrier)-quote)*Forecast!J33 | K8: =(delivery_rate*(1+carrier)-quote)*Forecast!K33 | L8: =(delivery_rate*(1+carrier)-quote)*Forecast!L33 | ... S8: =(delivery_rate*(1+carrier)-quote)*Forecast!S33 | T8: =SUM(B8:M8) | U8: =SUM(B8:S8)
A9: B. Delivery charge on small website orders | B9: 0 | C9: 0 | D9: =Forecast!D7*affected*((1-loss)*charge_exvat-loss*D6) | E9: =Forecast!E7*affected*((1-loss)*charge_exvat-loss*E6) | F9: =Forecast!F7*affected*((1-loss)*charge_exvat-loss*F6) | G9: =Forecast!G7*affected*((1-loss)*charge_exvat-loss*G6) | H9: =Forecast!H7*affected*((1-loss)*charge_exvat-loss*H6) | I9: =Forecast!I7*affected*((1-loss)*charge_exvat-loss*I6) | J9: =Forecast!J7*affected*((1-loss)*charge_exvat-loss*J6) | K9: =Forecast!K7*affected*((1-loss)*charge_exvat-loss*K6) | ... S9: =Forecast!S7*affected*((1-loss)*charge_exvat-loss*S6) | T9: =SUM(B9:M9) | U9: =SUM(B9:S9)
A10: C. 2% price rise | B10: 0 | C10: 0 | D10: =Forecast!D7*((1-volume_loss)*(D6+price_rise*Forecast!D12/Forecast!D7)-D6)+Forecast!D20*((1-volume_loss)*(D7+price_rise*Forecast!D25/Forecast!D20*(1-fee_rate))-D7) | E10: =Forecast!E7*((1-volume_loss)*(E6+price_rise*Forecast!E12/Forecast!E7)-E6)+Forecast!E20*((1-volume_loss)*(E7+price_rise*Forecast!E25/Forecast!E20*(1-fee_rate))-E7) | F10: =Forecast!F7*((1-volume_loss)*(F6+price_rise*Forecast!F12/Forecast!F7)-F6)+Forecast!F20*((1-volume_loss)*(F7+price_rise*Forecast!F25/Forecast!F20*(1-fee_rate))-F7) | G10: =Forecast!G7*((1-volume_loss)*(G6+price_rise*Forecast!G12/Forecast!G7)-G6)+Forecast!G20*((1-volume_loss)*(G7+price_rise*Forecast!G25/Forecast!G20*(1-fee_rate))-G7) | H10: =Forecast!H7*((1-volume_loss)*(H6+price_rise*Forecast!H12/Forecast!H7)-H6)+Forecast!H20*((1-volume_loss)*(H7+price_rise*Forecast!H25/Forecast!H20*(1-fee_rate))-H7) | I10: =Forecast!I7*((1-volume_loss)*(I6+price_rise*Forecast!I12/Forecast!I7)-I6)+Forecast!I20*((1-volume_loss)*(I7+price_rise*Forecast!I25/Forecast!I20*(1-fee_rate))-I7) | J10: =Forecast!J7*((1-volume_loss)*(J6+price_rise*Forecast!J12/Forecast!J7)-J6)+Forecast!J20*((1-volume_loss)*(J7+price_rise*Forecast!J25/Forecast!J20*(1-fee_rate))-J7) | K10: =Forecast!K7*((1-volume_loss)*(K6+price_rise*Forecast!K12/Forecast!K7)-K6)+Forecast!K20*((1-volume_loss)*(K7+price_rise*Forecast!K25/Forecast!K20*(1-fee_rate))-K7) | ... S10: =Forecast!S7*((1-volume_loss)*(S6+price_rise*Forecast!S12/Forecast!S7)-S6)+Forecast!S20*((1-volume_loss)*(S7+price_rise*Forecast!S25/Forecast!S20*(1-fee_rate))-S7) | T10: =SUM(B10:M10) | U10: =SUM(B10:S10)
A12: Break-even, option B: share of affected orders we can lose | B12: =charge_exvat/(charge_exvat+SUMPRODUCT(B6:M6,Forecast!B7:M7)/Forecast!T7)
A13: Break-even, option C: share of orders we can lose | B13: =price_rise*(Forecast!T12+Forecast!T25*(1-fee_rate))/((Forecast!T12+Forecast!T14+Forecast!T15+Forecast!T25+Forecast!T27+Forecast!T28+Forecast!T29)+price_rise*(Forecast!T12+Forecast!T25*(1-fee_rate)))
